<mujoco model="five_bar_mechanism">
    <compiler angle="degree" coordinate="local"/>
    <option timestep="0.001"/>

    <default>
        <geom type="capsule" size="0.02" rgba="0.8 0.4 0.4 0.2" contype="0" conaffinity="0"  density="50000"/>
        <joint damping="0.2" frictionloss="0.8"/>
    </default>

    <worldbody>
        <!-- Base -->
        <body name="base" pos="0 0 0">
            <geom fromto="-0.1 0 0 0.1 0 0" rgba="1 0 0 0.5"/>
            <!-- Left link 1 -->
            <body name="left_link1" pos="-0.1 0 0">
                <joint name="left_joint1" type="hinge" axis="0 0 1"/>
                <geom fromto="0 0 0 -0.2 0 0" rgba="0 1 0 0.5"/>
                <!-- Left link 2 -->
                <body name="left_link2" pos="-0.2 0 0">
                    <joint name="left_joint2" type="hinge" axis="0 0 1"/>
                    <geom fromto="0 0 0 -0.2 0 0"/>                    
                    <site name="left_site" pos="-0.2 0 0" size="0.01"/>
                        <!-- End-effector connected to left_link2 -->
                    <body name="ee" pos="-0.2 0 0">
                        <joint name="ee_joint" type="hinge" axis="0 0 1" limited="true" range="-120 -10"/>
                        <geom type="sphere" size="0.01" rgba="0.2 0.6 0.9 1"/>
                        <site name="ee_site" pos="0 0 0" size="0.01"/>
                    </body>
                </body>
            </body>

            <!-- Right link 1 -->
            <body name="right_link1" pos="0.1 0 0">
                <joint name="right_joint1" type="hinge" axis="0 0 1"/>
                <geom fromto="0 0 0 0.2 0 0" rgba="0 0 1 0.5"/>
                <!-- Right link 2 -->
                <body name="right_link2" pos="0.2 0 0">
                    <joint name="right_joint2" type="hinge" axis="0 0 1"/>
                    <geom fromto="0 0 0 0.2 0 0"/>                
                    <site name="right_site" pos="0.2 0 0" size="0.01"/>                    
                </body>
            </body>                    
        </body>
    </worldbody>

    <!-- Tendons or equality constraints would be needed to constrain the 5-bar kinematics -->

    <actuator>
        <motor joint="left_joint1" ctrlrange="-10 10"/>
        <motor joint="right_joint1" ctrlrange="-10 10"/>
    </actuator>

    <equality>
        <weld site1="right_site" site2="ee_site"/>
    </equality> 

</mujoco>
